{"uuid": "8498b44b-1e49-4f50-80d8-093c82a4fa64", "children": ["f3eb9eda-d3bc-4dba-b213-bfbc805a5a07", "2f3180c4-e25d-43d0-93df-6110faee29e1", "01fdf83f-5bcf-4452-8b8c-dfce2137e1ac", "f111594f-4c30-417f-ae87-e4675e94a65e", "a7375e30-9a31-46f5-8066-fc97e85c0aac", "f729527f-38a3-4d49-bfd8-26552e6c6e85", "19a18c1b-f3c8-4599-9b74-09839c7fd855", "92d532c6-6feb-4ef6-bec5-a184861fc6e5", "58298f4d-7798-499f-8cb1-cb5dd1862893", "25a22fc0-d6fc-4b40-b55c-7309aa9d9e20", "c8270a5f-7398-437b-bba8-adbf0b8b9559", "8f51b30c-49be-4d40-a8f1-cf659b46dec5", "ab5c2a35-e712-482c-924a-4399ca373a6b", "a3168eb5-674a-4396-a955-5d16345b43dc"], "befores": [{"name": "init_driver", "status": "passed", "start": 1678887532627, "stop": 1678887533778}], "afters": [{"name": "init_driver::0", "status": "broken", "statusDetails": {"message": "urllib3.exceptions.MaxRetryError: HTTPConnectionPool(host='localhost', port=36901): Max retries exceeded with url: /session/461f59ff89f2c378f1521a213aec8e70/cookie (Caused by NewConnectionError('<urllib3.connection.HTTPConnection object at 0x7f4e731ceb60>: Failed to establish a new connection: [Errno 111] Connection refused'))\n", "trace": "  File \"/usr/local/lib/python3.10/dist-packages/allure_commons/_allure.py\", line 221, in __call__\n    return self._fixture_function(*args, **kwargs)\n  File \"/usr/local/lib/python3.10/dist-packages/_pytest/fixtures.py\", line 916, in _teardown_yield_fixture\n    next(it)\n  File \"/home/sujith/codebase/BGE_Framework_Design/Test_Suites/conftest.py\", line 29, in init_driver\n    driver.delete_all_cookies()\n  File \"/home/sujith/.local/lib/python3.10/site-packages/selenium/webdriver/remote/webdriver.py\", line 730, in delete_all_cookies\n    self.execute(Command.DELETE_ALL_COOKIES)\n  File \"/home/sujith/.local/lib/python3.10/site-packages/selenium/webdriver/remote/webdriver.py\", line 442, in execute\n    response = self.command_executor.execute(driver_command, params)\n  File \"/home/sujith/.local/lib/python3.10/site-packages/selenium/webdriver/remote/remote_connection.py\", line 294, in execute\n    return self._request(command_info[0], url, body=data)\n  File \"/home/sujith/.local/lib/python3.10/site-packages/selenium/webdriver/remote/remote_connection.py\", line 316, in _request\n    response = self._conn.request(method, url, body=body, headers=headers)\n  File \"/home/sujith/.local/lib/python3.10/site-packages/urllib3/request.py\", line 74, in request\n    return self.request_encode_url(\n  File \"/home/sujith/.local/lib/python3.10/site-packages/urllib3/request.py\", line 96, in request_encode_url\n    return self.urlopen(method, url, **extra_kw)\n  File \"/home/sujith/.local/lib/python3.10/site-packages/urllib3/poolmanager.py\", line 376, in urlopen\n    response = conn.urlopen(method, u.request_uri, **kw)\n  File \"/home/sujith/.local/lib/python3.10/site-packages/urllib3/connectionpool.py\", line 815, in urlopen\n    return self.urlopen(\n  File \"/home/sujith/.local/lib/python3.10/site-packages/urllib3/connectionpool.py\", line 815, in urlopen\n    return self.urlopen(\n  File \"/home/sujith/.local/lib/python3.10/site-packages/urllib3/connectionpool.py\", line 815, in urlopen\n    return self.urlopen(\n  File \"/home/sujith/.local/lib/python3.10/site-packages/urllib3/connectionpool.py\", line 787, in urlopen\n    retries = retries.increment(\n  File \"/home/sujith/.local/lib/python3.10/site-packages/urllib3/util/retry.py\", line 592, in increment\n    raise MaxRetryError(_pool, url, error or ResponseError(cause))\n"}, "start": 1678887577090, "stop": 1678887577093}], "start": 1678887532627, "stop": 1678887577094}