{"uuid": "72856b7a-223e-4b61-ad92-22cd6c266f4a", "children": ["0b4cca71-d7da-4a2d-8c97-dfe1f7ff2582", "a4dcc863-e34b-4492-85c4-42c9ee57c677", "9d2f8f1f-ecc4-4fff-b5a8-0615c28a5f02", "2f950d1f-64fd-4bc9-9e3d-05b4731354a7", "9f61b740-1972-4919-9623-69ce55b482b7", "12806ffb-403e-4540-93fe-d816cbac8e49", "3ce1f5c6-fd46-464b-93eb-5721c95067f2", "1df257e3-c367-4271-ad35-26e9c4ab9913", "0a5a2ed7-f67d-4933-b270-c6e7fb9100fd", "3683dcf1-0f6b-4a08-a74d-8c90d8a1806c", "0fc51567-a967-46f3-83bb-82ac56d9aa66", "fbe44107-e6c5-42ab-9e9d-09004a25eba1", "4f134d93-fb27-4982-9d5b-5576d395db2f", "e95e69de-689e-4072-88e7-1193a2ac7d0f", "b0e29fea-5310-42bb-a80c-52e93826d983"], "befores": [{"name": "init_driver", "status": "passed", "start": 1678876596421, "stop": 1678876597590}], "afters": [{"name": "init_driver::0", "status": "broken", "statusDetails": {"message": "urllib3.exceptions.MaxRetryError: HTTPConnectionPool(host='localhost', port=40839): Max retries exceeded with url: /session/22682d325259e50486328fd05f9c2a61/cookie (Caused by NewConnectionError('<urllib3.connection.HTTPConnection object at 0x7fcb9eedf2b0>: Failed to establish a new connection: [Errno 111] Connection refused'))\n", "trace": "  File \"/usr/local/lib/python3.10/dist-packages/allure_commons/_allure.py\", line 221, in __call__\n    return self._fixture_function(*args, **kwargs)\n  File \"/usr/local/lib/python3.10/dist-packages/_pytest/fixtures.py\", line 916, in _teardown_yield_fixture\n    next(it)\n  File \"/home/sujith/codebase/BGE_Framework_Design/Test_Suites/conftest.py\", line 29, in init_driver\n    driver.delete_all_cookies()\n  File \"/home/sujith/.local/lib/python3.10/site-packages/selenium/webdriver/remote/webdriver.py\", line 730, in delete_all_cookies\n    self.execute(Command.DELETE_ALL_COOKIES)\n  File \"/home/sujith/.local/lib/python3.10/site-packages/selenium/webdriver/remote/webdriver.py\", line 442, in execute\n    response = self.command_executor.execute(driver_command, params)\n  File \"/home/sujith/.local/lib/python3.10/site-packages/selenium/webdriver/remote/remote_connection.py\", line 294, in execute\n    return self._request(command_info[0], url, body=data)\n  File \"/home/sujith/.local/lib/python3.10/site-packages/selenium/webdriver/remote/remote_connection.py\", line 316, in _request\n    response = self._conn.request(method, url, body=body, headers=headers)\n  File \"/home/sujith/.local/lib/python3.10/site-packages/urllib3/request.py\", line 74, in request\n    return self.request_encode_url(\n  File \"/home/sujith/.local/lib/python3.10/site-packages/urllib3/request.py\", line 96, in request_encode_url\n    return self.urlopen(method, url, **extra_kw)\n  File \"/home/sujith/.local/lib/python3.10/site-packages/urllib3/poolmanager.py\", line 376, in urlopen\n    response = conn.urlopen(method, u.request_uri, **kw)\n  File \"/home/sujith/.local/lib/python3.10/site-packages/urllib3/connectionpool.py\", line 815, in urlopen\n    return self.urlopen(\n  File \"/home/sujith/.local/lib/python3.10/site-packages/urllib3/connectionpool.py\", line 815, in urlopen\n    return self.urlopen(\n  File \"/home/sujith/.local/lib/python3.10/site-packages/urllib3/connectionpool.py\", line 815, in urlopen\n    return self.urlopen(\n  File \"/home/sujith/.local/lib/python3.10/site-packages/urllib3/connectionpool.py\", line 787, in urlopen\n    retries = retries.increment(\n  File \"/home/sujith/.local/lib/python3.10/site-packages/urllib3/util/retry.py\", line 592, in increment\n    raise MaxRetryError(_pool, url, error or ResponseError(cause))\n"}, "start": 1678876685245, "stop": 1678876685247}], "start": 1678876596421, "stop": 1678876685247}