{"uuid": "5c411182-2bc1-41bc-9089-77b1ce939124", "children": ["79209280-e105-4ea6-832b-4cc952c4e185", "14067818-0e6a-464d-acdb-e81eee75409c", "77d6620d-d599-4db3-8b6c-6dc3c18999f2", "4c2d6752-b8c4-4eca-a7e8-5abc0033e734", "0aff6408-47ad-4142-aee7-80be855f3764", "cc87b9d4-843d-4da0-a146-a999cb205b83", "065f9da9-8195-4588-a799-38ff10486c48", "e01e6ee2-7703-4515-bc5b-7c6c25e73e37", "37dbee81-b100-4574-8611-7a5c55f3f8b3", "971d1c45-2a7b-41f1-b004-b441d29c3930", "853e8e48-c6ec-46d3-adf8-73deb7e3c070"], "befores": [{"name": "init_driver", "status": "passed", "start": 1678876704661, "stop": 1678876705814}], "afters": [{"name": "init_driver::0", "status": "broken", "statusDetails": {"message": "urllib3.exceptions.MaxRetryError: HTTPConnectionPool(host='localhost', port=48229): Max retries exceeded with url: /session/dc1ad308a28a58b46058881b0c199bb3/cookie (Caused by NewConnectionError('<urllib3.connection.HTTPConnection object at 0x7f1330282bc0>: Failed to establish a new connection: [Errno 111] Connection refused'))\n", "trace": "  File \"/usr/local/lib/python3.10/dist-packages/allure_commons/_allure.py\", line 221, in __call__\n    return self._fixture_function(*args, **kwargs)\n  File \"/usr/local/lib/python3.10/dist-packages/_pytest/fixtures.py\", line 916, in _teardown_yield_fixture\n    next(it)\n  File \"/home/sujith/codebase/BGE_Framework_Design/Test_Suites/conftest.py\", line 29, in init_driver\n    driver.delete_all_cookies()\n  File \"/home/sujith/.local/lib/python3.10/site-packages/selenium/webdriver/remote/webdriver.py\", line 730, in delete_all_cookies\n    self.execute(Command.DELETE_ALL_COOKIES)\n  File \"/home/sujith/.local/lib/python3.10/site-packages/selenium/webdriver/remote/webdriver.py\", line 442, in execute\n    response = self.command_executor.execute(driver_command, params)\n  File \"/home/sujith/.local/lib/python3.10/site-packages/selenium/webdriver/remote/remote_connection.py\", line 294, in execute\n    return self._request(command_info[0], url, body=data)\n  File \"/home/sujith/.local/lib/python3.10/site-packages/selenium/webdriver/remote/remote_connection.py\", line 316, in _request\n    response = self._conn.request(method, url, body=body, headers=headers)\n  File \"/home/sujith/.local/lib/python3.10/site-packages/urllib3/request.py\", line 74, in request\n    return self.request_encode_url(\n  File \"/home/sujith/.local/lib/python3.10/site-packages/urllib3/request.py\", line 96, in request_encode_url\n    return self.urlopen(method, url, **extra_kw)\n  File \"/home/sujith/.local/lib/python3.10/site-packages/urllib3/poolmanager.py\", line 376, in urlopen\n    response = conn.urlopen(method, u.request_uri, **kw)\n  File \"/home/sujith/.local/lib/python3.10/site-packages/urllib3/connectionpool.py\", line 815, in urlopen\n    return self.urlopen(\n  File \"/home/sujith/.local/lib/python3.10/site-packages/urllib3/connectionpool.py\", line 815, in urlopen\n    return self.urlopen(\n  File \"/home/sujith/.local/lib/python3.10/site-packages/urllib3/connectionpool.py\", line 815, in urlopen\n    return self.urlopen(\n  File \"/home/sujith/.local/lib/python3.10/site-packages/urllib3/connectionpool.py\", line 787, in urlopen\n    retries = retries.increment(\n  File \"/home/sujith/.local/lib/python3.10/site-packages/urllib3/util/retry.py\", line 592, in increment\n    raise MaxRetryError(_pool, url, error or ResponseError(cause))\n"}, "start": 1678876743113, "stop": 1678876743116}], "start": 1678876704661, "stop": 1678876743116}