{"uuid": "37ad794b-6882-49a8-af03-24cb3857be71", "children": ["0b7ab4bc-fdd0-4375-bfb8-3394d9b3c12a", "8b5b7b0f-136b-487b-879e-2d4d8c65f00e", "fef86a07-e45f-4e3f-9e74-20f3fdb5f6a5", "c11e2225-965f-4143-b241-ff2c2aaa393c", "ab8b090a-3ce3-453a-82d8-12a5dbf67789", "99c4d1b0-c295-4f61-a744-017cf19b2e1e", "d26d9f87-1367-48b4-b716-9519d1bf8e04", "c816cb4d-3751-4e1a-abf9-53d1a1e8259f", "a3e94c2a-8ac5-427a-bda3-3d870fa597c9", "919968cd-467a-4fc6-9f75-2829a5cf7439", "5e91599c-1807-42be-9b00-8bcbdaed76e6", "a43faee4-998f-400f-a0d3-abbcd2684096", "91b252b7-a740-4c6c-9b27-1472cb8468a0", "ab51dd2e-7c1e-4e4d-a326-ea7d10f24a30", "52f0f920-682f-4c53-80eb-45f8031f5066", "642928dc-d0fa-422f-9fc4-27c4f8ac0f94", "679b358a-a8b8-461e-b2b6-3e093dc19a3c"], "befores": [{"name": "init_driver", "status": "passed", "start": 1678877198274, "stop": 1678877199435}], "afters": [{"name": "init_driver::0", "status": "broken", "statusDetails": {"message": "urllib3.exceptions.MaxRetryError: HTTPConnectionPool(host='localhost', port=52009): Max retries exceeded with url: /session/d044dac84d45f1f1176db8e1122eea0b/cookie (Caused by NewConnectionError('<urllib3.connection.HTTPConnection object at 0x7f6c0b4a07f0>: Failed to establish a new connection: [Errno 111] Connection refused'))\n", "trace": "  File \"/usr/local/lib/python3.10/dist-packages/allure_commons/_allure.py\", line 221, in __call__\n    return self._fixture_function(*args, **kwargs)\n  File \"/usr/local/lib/python3.10/dist-packages/_pytest/fixtures.py\", line 916, in _teardown_yield_fixture\n    next(it)\n  File \"/home/sujith/codebase/BGE_Framework_Design/Test_Suites/conftest.py\", line 29, in init_driver\n    driver.delete_all_cookies()\n  File \"/home/sujith/.local/lib/python3.10/site-packages/selenium/webdriver/remote/webdriver.py\", line 730, in delete_all_cookies\n    self.execute(Command.DELETE_ALL_COOKIES)\n  File \"/home/sujith/.local/lib/python3.10/site-packages/selenium/webdriver/remote/webdriver.py\", line 442, in execute\n    response = self.command_executor.execute(driver_command, params)\n  File \"/home/sujith/.local/lib/python3.10/site-packages/selenium/webdriver/remote/remote_connection.py\", line 294, in execute\n    return self._request(command_info[0], url, body=data)\n  File \"/home/sujith/.local/lib/python3.10/site-packages/selenium/webdriver/remote/remote_connection.py\", line 316, in _request\n    response = self._conn.request(method, url, body=body, headers=headers)\n  File \"/home/sujith/.local/lib/python3.10/site-packages/urllib3/request.py\", line 74, in request\n    return self.request_encode_url(\n  File \"/home/sujith/.local/lib/python3.10/site-packages/urllib3/request.py\", line 96, in request_encode_url\n    return self.urlopen(method, url, **extra_kw)\n  File \"/home/sujith/.local/lib/python3.10/site-packages/urllib3/poolmanager.py\", line 376, in urlopen\n    response = conn.urlopen(method, u.request_uri, **kw)\n  File \"/home/sujith/.local/lib/python3.10/site-packages/urllib3/connectionpool.py\", line 815, in urlopen\n    return self.urlopen(\n  File \"/home/sujith/.local/lib/python3.10/site-packages/urllib3/connectionpool.py\", line 815, in urlopen\n    return self.urlopen(\n  File \"/home/sujith/.local/lib/python3.10/site-packages/urllib3/connectionpool.py\", line 815, in urlopen\n    return self.urlopen(\n  File \"/home/sujith/.local/lib/python3.10/site-packages/urllib3/connectionpool.py\", line 787, in urlopen\n    retries = retries.increment(\n  File \"/home/sujith/.local/lib/python3.10/site-packages/urllib3/util/retry.py\", line 592, in increment\n    raise MaxRetryError(_pool, url, error or ResponseError(cause))\n"}, "start": 1678877261596, "stop": 1678877261599}], "start": 1678877198274, "stop": 1678877261599}