{"uuid": "81be8442-8576-4159-8a5c-63a9c4145368", "children": ["b56fc75b-1989-419b-b516-f093ce78d84b", "28b036e5-cf9e-4a0f-92d1-6d8fa5a6f800", "2e16b245-660c-4b47-a707-36ad40ace5b6", "95cb0475-2db8-406f-b8c3-40e50d376eff", "d21b236c-410e-4f49-8d9d-f471c431d271", "7f515939-c97d-4e3b-8ede-70595dd2dbc3", "2bb80ea2-51b3-4d94-97f0-38d4bc02989e", "4bde1913-f89c-42bf-959b-2ab749d65b3d", "16efd93e-af5f-4636-9102-3957e84f2867", "14f281fd-37aa-45a5-9f59-b6fcf47608c0", "f9b4d357-8161-421d-91eb-cb25b48d1538", "574efa9c-4332-4f17-9be0-78ff0278a017", "4adc126e-090f-46fb-a3d9-b6ec521a3ff2", "38fdd06c-435f-4c9c-b9aa-0c1c01c2bc96"], "befores": [{"name": "init_driver", "status": "passed", "start": 1678885841505, "stop": 1678885842685}], "afters": [{"name": "init_driver::0", "status": "broken", "statusDetails": {"message": "urllib3.exceptions.MaxRetryError: HTTPConnectionPool(host='localhost', port=37823): Max retries exceeded with url: /session/2854baddbe9192d183331e3243edc6f7/cookie (Caused by NewConnectionError('<urllib3.connection.HTTPConnection object at 0x7f03cf9d2e60>: Failed to establish a new connection: [Errno 111] Connection refused'))\n", "trace": "  File \"/usr/local/lib/python3.10/dist-packages/allure_commons/_allure.py\", line 221, in __call__\n    return self._fixture_function(*args, **kwargs)\n  File \"/usr/local/lib/python3.10/dist-packages/_pytest/fixtures.py\", line 916, in _teardown_yield_fixture\n    next(it)\n  File \"/home/sujith/codebase/BGE_Framework_Design/Test_Suites/conftest.py\", line 29, in init_driver\n    driver.delete_all_cookies()\n  File \"/home/sujith/.local/lib/python3.10/site-packages/selenium/webdriver/remote/webdriver.py\", line 730, in delete_all_cookies\n    self.execute(Command.DELETE_ALL_COOKIES)\n  File \"/home/sujith/.local/lib/python3.10/site-packages/selenium/webdriver/remote/webdriver.py\", line 442, in execute\n    response = self.command_executor.execute(driver_command, params)\n  File \"/home/sujith/.local/lib/python3.10/site-packages/selenium/webdriver/remote/remote_connection.py\", line 294, in execute\n    return self._request(command_info[0], url, body=data)\n  File \"/home/sujith/.local/lib/python3.10/site-packages/selenium/webdriver/remote/remote_connection.py\", line 316, in _request\n    response = self._conn.request(method, url, body=body, headers=headers)\n  File \"/home/sujith/.local/lib/python3.10/site-packages/urllib3/request.py\", line 74, in request\n    return self.request_encode_url(\n  File \"/home/sujith/.local/lib/python3.10/site-packages/urllib3/request.py\", line 96, in request_encode_url\n    return self.urlopen(method, url, **extra_kw)\n  File \"/home/sujith/.local/lib/python3.10/site-packages/urllib3/poolmanager.py\", line 376, in urlopen\n    response = conn.urlopen(method, u.request_uri, **kw)\n  File \"/home/sujith/.local/lib/python3.10/site-packages/urllib3/connectionpool.py\", line 815, in urlopen\n    return self.urlopen(\n  File \"/home/sujith/.local/lib/python3.10/site-packages/urllib3/connectionpool.py\", line 815, in urlopen\n    return self.urlopen(\n  File \"/home/sujith/.local/lib/python3.10/site-packages/urllib3/connectionpool.py\", line 815, in urlopen\n    return self.urlopen(\n  File \"/home/sujith/.local/lib/python3.10/site-packages/urllib3/connectionpool.py\", line 787, in urlopen\n    retries = retries.increment(\n  File \"/home/sujith/.local/lib/python3.10/site-packages/urllib3/util/retry.py\", line 592, in increment\n    raise MaxRetryError(_pool, url, error or ResponseError(cause))\n"}, "start": 1678885899082, "stop": 1678885899085}], "start": 1678885841505, "stop": 1678885899085}