{"uuid": "ea34433d-2818-4e0c-8706-8897aaa7a915", "children": ["6c71ec65-21d4-478b-bba6-8422d70faeca", "cfb3b850-9623-40bf-98c8-039496e070d9", "083e48bd-ce90-47a1-84cc-7af6636fc423", "b7c580ca-3941-4c57-8332-18e916e8f89c", "02898ab9-4003-418c-895e-894c8f8bf6d8", "f302ca45-7948-455b-a070-32301b0ea308", "3f6c84b1-5783-42ee-befa-b44671c2bd9c", "d1a0120b-c1a3-42e6-ab57-a8946ea87cb0", "2d3dbc4d-b12b-404b-bb2b-d7611bc76f43", "012de981-1067-49e7-8ae7-b1891de4f03a", "424d9eac-0dbd-4bb3-8497-c06449926dc6", "06de82e9-6cf7-4c55-a6c7-db6bbb2a932e", "8d5f20f2-2d27-4c01-8908-9d3817dac33a", "a885b40c-9a64-4558-97b8-5f4688ff3e69"], "befores": [{"name": "init_driver", "status": "passed", "start": 1678885315921, "stop": 1678885317085}], "afters": [{"name": "init_driver::0", "status": "broken", "statusDetails": {"message": "urllib3.exceptions.MaxRetryError: HTTPConnectionPool(host='localhost', port=48485): Max retries exceeded with url: /session/acb4c7557471c796d276e8cc4ba1262b/cookie (Caused by NewConnectionError('<urllib3.connection.HTTPConnection object at 0x7fc21fed6e60>: Failed to establish a new connection: [Errno 111] Connection refused'))\n", "trace": "  File \"/usr/local/lib/python3.10/dist-packages/allure_commons/_allure.py\", line 221, in __call__\n    return self._fixture_function(*args, **kwargs)\n  File \"/usr/local/lib/python3.10/dist-packages/_pytest/fixtures.py\", line 916, in _teardown_yield_fixture\n    next(it)\n  File \"/home/sujith/codebase/BGE_Framework_Design/Test_Suites/conftest.py\", line 29, in init_driver\n    driver.delete_all_cookies()\n  File \"/home/sujith/.local/lib/python3.10/site-packages/selenium/webdriver/remote/webdriver.py\", line 730, in delete_all_cookies\n    self.execute(Command.DELETE_ALL_COOKIES)\n  File \"/home/sujith/.local/lib/python3.10/site-packages/selenium/webdriver/remote/webdriver.py\", line 442, in execute\n    response = self.command_executor.execute(driver_command, params)\n  File \"/home/sujith/.local/lib/python3.10/site-packages/selenium/webdriver/remote/remote_connection.py\", line 294, in execute\n    return self._request(command_info[0], url, body=data)\n  File \"/home/sujith/.local/lib/python3.10/site-packages/selenium/webdriver/remote/remote_connection.py\", line 316, in _request\n    response = self._conn.request(method, url, body=body, headers=headers)\n  File \"/home/sujith/.local/lib/python3.10/site-packages/urllib3/request.py\", line 74, in request\n    return self.request_encode_url(\n  File \"/home/sujith/.local/lib/python3.10/site-packages/urllib3/request.py\", line 96, in request_encode_url\n    return self.urlopen(method, url, **extra_kw)\n  File \"/home/sujith/.local/lib/python3.10/site-packages/urllib3/poolmanager.py\", line 376, in urlopen\n    response = conn.urlopen(method, u.request_uri, **kw)\n  File \"/home/sujith/.local/lib/python3.10/site-packages/urllib3/connectionpool.py\", line 815, in urlopen\n    return self.urlopen(\n  File \"/home/sujith/.local/lib/python3.10/site-packages/urllib3/connectionpool.py\", line 815, in urlopen\n    return self.urlopen(\n  File \"/home/sujith/.local/lib/python3.10/site-packages/urllib3/connectionpool.py\", line 815, in urlopen\n    return self.urlopen(\n  File \"/home/sujith/.local/lib/python3.10/site-packages/urllib3/connectionpool.py\", line 787, in urlopen\n    retries = retries.increment(\n  File \"/home/sujith/.local/lib/python3.10/site-packages/urllib3/util/retry.py\", line 592, in increment\n    raise MaxRetryError(_pool, url, error or ResponseError(cause))\n"}, "start": 1678885357610, "stop": 1678885357613}], "start": 1678885315921, "stop": 1678885357613}