{"uuid": "269ecae6-d312-4a76-9028-6f012d7afe3e", "children": ["388bee9d-4749-44ff-ace9-3688aab7dd95", "be40b3bb-6b95-4d23-a869-00e6ba3f3704", "51cb0aff-45f5-470f-9bff-c28730349123", "df630e3b-80c4-45f9-894c-44738a919770", "1eee3243-c3d2-436b-9777-1d2cc2c6e941", "48f09678-ed30-4bf9-8901-e4c179a4669c", "4d0b6df5-4ac5-4e81-857a-7d213ee43a51", "ae1326f3-4f49-4bae-b124-509173f7dda8", "ce8a2fe7-64e9-4d86-a762-d3d9757d4fb0", "0e88fe16-2751-4773-97c6-57a306714016", "bf0d2fca-0002-44c3-b975-3f7ab4177169", "604d2a3d-44de-4b34-97d1-75629a1a28d7", "4d595097-ea5f-4974-a1ef-43fc69bc022f", "529baac5-8e68-4878-a158-daa1cf8cefe6", "e2ff6a47-79a1-4912-91a3-4c03bc9cb4cf"], "befores": [{"name": "init_driver", "status": "passed", "start": 1678874194970, "stop": 1678874196103}], "afters": [{"name": "init_driver::0", "status": "broken", "statusDetails": {"message": "urllib3.exceptions.MaxRetryError: HTTPConnectionPool(host='localhost', port=42319): Max retries exceeded with url: /session/5a792e676201da80b471b781902fff13/cookie (Caused by NewConnectionError('<urllib3.connection.HTTPConnection object at 0x7faf436636d0>: Failed to establish a new connection: [Errno 111] Connection refused'))\n", "trace": "  File \"/usr/local/lib/python3.10/dist-packages/allure_commons/_allure.py\", line 221, in __call__\n    return self._fixture_function(*args, **kwargs)\n  File \"/usr/local/lib/python3.10/dist-packages/_pytest/fixtures.py\", line 916, in _teardown_yield_fixture\n    next(it)\n  File \"/home/sujith/codebase/BGE_Framework_Design/Test_Suites/conftest.py\", line 29, in init_driver\n    driver.delete_all_cookies()\n  File \"/home/sujith/.local/lib/python3.10/site-packages/selenium/webdriver/remote/webdriver.py\", line 730, in delete_all_cookies\n    self.execute(Command.DELETE_ALL_COOKIES)\n  File \"/home/sujith/.local/lib/python3.10/site-packages/selenium/webdriver/remote/webdriver.py\", line 442, in execute\n    response = self.command_executor.execute(driver_command, params)\n  File \"/home/sujith/.local/lib/python3.10/site-packages/selenium/webdriver/remote/remote_connection.py\", line 294, in execute\n    return self._request(command_info[0], url, body=data)\n  File \"/home/sujith/.local/lib/python3.10/site-packages/selenium/webdriver/remote/remote_connection.py\", line 316, in _request\n    response = self._conn.request(method, url, body=body, headers=headers)\n  File \"/home/sujith/.local/lib/python3.10/site-packages/urllib3/request.py\", line 74, in request\n    return self.request_encode_url(\n  File \"/home/sujith/.local/lib/python3.10/site-packages/urllib3/request.py\", line 96, in request_encode_url\n    return self.urlopen(method, url, **extra_kw)\n  File \"/home/sujith/.local/lib/python3.10/site-packages/urllib3/poolmanager.py\", line 376, in urlopen\n    response = conn.urlopen(method, u.request_uri, **kw)\n  File \"/home/sujith/.local/lib/python3.10/site-packages/urllib3/connectionpool.py\", line 815, in urlopen\n    return self.urlopen(\n  File \"/home/sujith/.local/lib/python3.10/site-packages/urllib3/connectionpool.py\", line 815, in urlopen\n    return self.urlopen(\n  File \"/home/sujith/.local/lib/python3.10/site-packages/urllib3/connectionpool.py\", line 815, in urlopen\n    return self.urlopen(\n  File \"/home/sujith/.local/lib/python3.10/site-packages/urllib3/connectionpool.py\", line 787, in urlopen\n    retries = retries.increment(\n  File \"/home/sujith/.local/lib/python3.10/site-packages/urllib3/util/retry.py\", line 592, in increment\n    raise MaxRetryError(_pool, url, error or ResponseError(cause))\n"}, "start": 1678874254043, "stop": 1678874254046}], "start": 1678874194970, "stop": 1678874254046}