{"uuid": "6c5de1e8-7a3e-4b3f-ae0e-c5c64ce7a814", "children": ["f86a1f0d-95a1-4768-9ce1-1b2378aac932", "5f0b7aa2-4412-4a2c-94ad-af6d5579769d", "0a83e471-39c2-404b-8e24-7f96410961c8", "e3fd2a9d-1569-4301-a6d5-9c70a2d88391", "aca47b75-c1a7-46b2-ad95-1f24377581e9", "7060ff1e-3e1d-4d52-827a-b76d2e86d814", "99ea859a-d48f-477b-9e0c-77af98e098e5", "eb759abc-3ff7-4210-959d-fb83a1487810", "115464e0-4e96-4def-9779-1034c972ba3b", "7383b950-ce5a-4051-8377-497ed212f933", "5f7928f5-ea44-494f-8e18-80dbd5d32b96"], "befores": [{"name": "init_driver", "status": "passed", "start": 1678858200272, "stop": 1678858201435}], "afters": [{"name": "init_driver::0", "status": "broken", "statusDetails": {"message": "urllib3.exceptions.MaxRetryError: HTTPConnectionPool(host='localhost', port=60363): Max retries exceeded with url: /session/00c98210afae59700eaf68b13865c84b/cookie (Caused by NewConnectionError('<urllib3.connection.HTTPConnection object at 0x7fd2335626b0>: Failed to establish a new connection: [Errno 111] Connection refused'))\n", "trace": "  File \"/usr/local/lib/python3.10/dist-packages/allure_commons/_allure.py\", line 221, in __call__\n    return self._fixture_function(*args, **kwargs)\n  File \"/usr/local/lib/python3.10/dist-packages/_pytest/fixtures.py\", line 916, in _teardown_yield_fixture\n    next(it)\n  File \"/home/sujith/codebase/BGE_Framework_Design/Test_Suites/conftest.py\", line 29, in init_driver\n    driver.delete_all_cookies()\n  File \"/home/sujith/.local/lib/python3.10/site-packages/selenium/webdriver/remote/webdriver.py\", line 730, in delete_all_cookies\n    self.execute(Command.DELETE_ALL_COOKIES)\n  File \"/home/sujith/.local/lib/python3.10/site-packages/selenium/webdriver/remote/webdriver.py\", line 442, in execute\n    response = self.command_executor.execute(driver_command, params)\n  File \"/home/sujith/.local/lib/python3.10/site-packages/selenium/webdriver/remote/remote_connection.py\", line 294, in execute\n    return self._request(command_info[0], url, body=data)\n  File \"/home/sujith/.local/lib/python3.10/site-packages/selenium/webdriver/remote/remote_connection.py\", line 316, in _request\n    response = self._conn.request(method, url, body=body, headers=headers)\n  File \"/home/sujith/.local/lib/python3.10/site-packages/urllib3/request.py\", line 74, in request\n    return self.request_encode_url(\n  File \"/home/sujith/.local/lib/python3.10/site-packages/urllib3/request.py\", line 96, in request_encode_url\n    return self.urlopen(method, url, **extra_kw)\n  File \"/home/sujith/.local/lib/python3.10/site-packages/urllib3/poolmanager.py\", line 376, in urlopen\n    response = conn.urlopen(method, u.request_uri, **kw)\n  File \"/home/sujith/.local/lib/python3.10/site-packages/urllib3/connectionpool.py\", line 815, in urlopen\n    return self.urlopen(\n  File \"/home/sujith/.local/lib/python3.10/site-packages/urllib3/connectionpool.py\", line 815, in urlopen\n    return self.urlopen(\n  File \"/home/sujith/.local/lib/python3.10/site-packages/urllib3/connectionpool.py\", line 815, in urlopen\n    return self.urlopen(\n  File \"/home/sujith/.local/lib/python3.10/site-packages/urllib3/connectionpool.py\", line 787, in urlopen\n    retries = retries.increment(\n  File \"/home/sujith/.local/lib/python3.10/site-packages/urllib3/util/retry.py\", line 592, in increment\n    raise MaxRetryError(_pool, url, error or ResponseError(cause))\n"}, "start": 1678858226989, "stop": 1678858226991}], "start": 1678858200272, "stop": 1678858226991}