{"uuid": "d6fbc32e-941b-41fe-b678-be2f934b98d3", "children": ["ebe0a652-9f88-4042-9f2d-696a894d89ce", "72f30d92-d205-4673-97b2-a121e61be604", "c42e1a5f-74a0-4431-a9da-a9a07a968699", "59ff7033-d1fc-4baf-ae89-be33b4f0b342", "8802e583-ead3-4b4e-a178-f695a069e64f", "d6b8d831-5709-4add-8760-57aa56d6b078", "a8fa1f31-27cf-4090-860b-fc86be49dd12", "063a20ee-8166-4fe6-90b8-92a45c7af3fd", "97da86a6-15cf-464f-9937-67e44688a3a1", "403ff5f7-b9c7-4164-aeff-2d277c9661c2", "259137cd-f3e7-427f-a92d-98d8bcdd670f"], "befores": [{"name": "init_driver", "status": "passed", "start": 1678887597371, "stop": 1678887598570}], "afters": [{"name": "init_driver::0", "status": "broken", "statusDetails": {"message": "urllib3.exceptions.MaxRetryError: HTTPConnectionPool(host='localhost', port=58621): Max retries exceeded with url: /session/9f13acdf261ecef1a8b1868fffd6d965/cookie (Caused by NewConnectionError('<urllib3.connection.HTTPConnection object at 0x7ff45f51f0a0>: Failed to establish a new connection: [Errno 111] Connection refused'))\n", "trace": "  File \"/usr/local/lib/python3.10/dist-packages/allure_commons/_allure.py\", line 221, in __call__\n    return self._fixture_function(*args, **kwargs)\n  File \"/usr/local/lib/python3.10/dist-packages/_pytest/fixtures.py\", line 916, in _teardown_yield_fixture\n    next(it)\n  File \"/home/sujith/codebase/BGE_Framework_Design/Test_Suites/conftest.py\", line 29, in init_driver\n    driver.delete_all_cookies()\n  File \"/home/sujith/.local/lib/python3.10/site-packages/selenium/webdriver/remote/webdriver.py\", line 730, in delete_all_cookies\n    self.execute(Command.DELETE_ALL_COOKIES)\n  File \"/home/sujith/.local/lib/python3.10/site-packages/selenium/webdriver/remote/webdriver.py\", line 442, in execute\n    response = self.command_executor.execute(driver_command, params)\n  File \"/home/sujith/.local/lib/python3.10/site-packages/selenium/webdriver/remote/remote_connection.py\", line 294, in execute\n    return self._request(command_info[0], url, body=data)\n  File \"/home/sujith/.local/lib/python3.10/site-packages/selenium/webdriver/remote/remote_connection.py\", line 316, in _request\n    response = self._conn.request(method, url, body=body, headers=headers)\n  File \"/home/sujith/.local/lib/python3.10/site-packages/urllib3/request.py\", line 74, in request\n    return self.request_encode_url(\n  File \"/home/sujith/.local/lib/python3.10/site-packages/urllib3/request.py\", line 96, in request_encode_url\n    return self.urlopen(method, url, **extra_kw)\n  File \"/home/sujith/.local/lib/python3.10/site-packages/urllib3/poolmanager.py\", line 376, in urlopen\n    response = conn.urlopen(method, u.request_uri, **kw)\n  File \"/home/sujith/.local/lib/python3.10/site-packages/urllib3/connectionpool.py\", line 815, in urlopen\n    return self.urlopen(\n  File \"/home/sujith/.local/lib/python3.10/site-packages/urllib3/connectionpool.py\", line 815, in urlopen\n    return self.urlopen(\n  File \"/home/sujith/.local/lib/python3.10/site-packages/urllib3/connectionpool.py\", line 815, in urlopen\n    return self.urlopen(\n  File \"/home/sujith/.local/lib/python3.10/site-packages/urllib3/connectionpool.py\", line 787, in urlopen\n    retries = retries.increment(\n  File \"/home/sujith/.local/lib/python3.10/site-packages/urllib3/util/retry.py\", line 592, in increment\n    raise MaxRetryError(_pool, url, error or ResponseError(cause))\n"}, "start": 1678887634538, "stop": 1678887634542}], "start": 1678887597371, "stop": 1678887634542}