{"uuid": "bd462777-b819-462d-bcda-ad0fa8aa2454", "children": ["d104aefd-8792-41e8-beaf-51177986d05a", "bf1ae963-d29f-4371-b60c-5d0d9a5d6d44", "43a2c5bc-e17b-4324-9743-9610c750dae7", "c87b0cc0-087a-4ca6-9c97-7f24a3fbcb4e", "0359d26c-1f0a-45d9-a249-e2eb30e13c45", "72c63058-00f7-406f-8a54-2e4e282e55bb", "8988a928-7b27-40e7-b108-03e1594ea560", "b3f78579-d655-44ba-b5fa-fecde4fec070", "ef6eb2b7-fee7-48b6-807c-62aec1a0b383", "325b9a05-244b-4028-b687-9ab3b26f9c8e", "2ce7678a-044f-4bcb-933f-94150b55d754", "e151b3b1-fbfc-45ab-9ef8-6bf0f8335d0d", "b33adc62-7161-4461-a4a3-1f6ca9349d3e", "1c699654-9129-492e-9843-dd78fa7d4018", "610cc538-e2f7-4313-9c92-484486c0e81d", "7f26b7e3-80d8-4ea1-8883-f0d89aec8a96", "618721a5-7a83-4e23-81fa-4da0b0367660"], "befores": [{"name": "init_driver", "status": "passed", "start": 1678874448518, "stop": 1678874449698}], "afters": [{"name": "init_driver::0", "status": "broken", "statusDetails": {"message": "urllib3.exceptions.MaxRetryError: HTTPConnectionPool(host='localhost', port=57353): Max retries exceeded with url: /session/c9ed40543dda66cc88ce91a89e7122c2/cookie (Caused by NewConnectionError('<urllib3.connection.HTTPConnection object at 0x7f076d585870>: Failed to establish a new connection: [Errno 111] Connection refused'))\n", "trace": "  File \"/usr/local/lib/python3.10/dist-packages/allure_commons/_allure.py\", line 221, in __call__\n    return self._fixture_function(*args, **kwargs)\n  File \"/usr/local/lib/python3.10/dist-packages/_pytest/fixtures.py\", line 916, in _teardown_yield_fixture\n    next(it)\n  File \"/home/sujith/codebase/BGE_Framework_Design/Test_Suites/conftest.py\", line 29, in init_driver\n    driver.delete_all_cookies()\n  File \"/home/sujith/.local/lib/python3.10/site-packages/selenium/webdriver/remote/webdriver.py\", line 730, in delete_all_cookies\n    self.execute(Command.DELETE_ALL_COOKIES)\n  File \"/home/sujith/.local/lib/python3.10/site-packages/selenium/webdriver/remote/webdriver.py\", line 442, in execute\n    response = self.command_executor.execute(driver_command, params)\n  File \"/home/sujith/.local/lib/python3.10/site-packages/selenium/webdriver/remote/remote_connection.py\", line 294, in execute\n    return self._request(command_info[0], url, body=data)\n  File \"/home/sujith/.local/lib/python3.10/site-packages/selenium/webdriver/remote/remote_connection.py\", line 316, in _request\n    response = self._conn.request(method, url, body=body, headers=headers)\n  File \"/home/sujith/.local/lib/python3.10/site-packages/urllib3/request.py\", line 74, in request\n    return self.request_encode_url(\n  File \"/home/sujith/.local/lib/python3.10/site-packages/urllib3/request.py\", line 96, in request_encode_url\n    return self.urlopen(method, url, **extra_kw)\n  File \"/home/sujith/.local/lib/python3.10/site-packages/urllib3/poolmanager.py\", line 376, in urlopen\n    response = conn.urlopen(method, u.request_uri, **kw)\n  File \"/home/sujith/.local/lib/python3.10/site-packages/urllib3/connectionpool.py\", line 815, in urlopen\n    return self.urlopen(\n  File \"/home/sujith/.local/lib/python3.10/site-packages/urllib3/connectionpool.py\", line 815, in urlopen\n    return self.urlopen(\n  File \"/home/sujith/.local/lib/python3.10/site-packages/urllib3/connectionpool.py\", line 815, in urlopen\n    return self.urlopen(\n  File \"/home/sujith/.local/lib/python3.10/site-packages/urllib3/connectionpool.py\", line 787, in urlopen\n    retries = retries.increment(\n  File \"/home/sujith/.local/lib/python3.10/site-packages/urllib3/util/retry.py\", line 592, in increment\n    raise MaxRetryError(_pool, url, error or ResponseError(cause))\n"}, "start": 1678874524090, "stop": 1678874524093}], "start": 1678874448518, "stop": 1678874524093}