{"uuid": "2b1d36b1-69ad-4b24-8b35-6531b63e759e", "children": ["ff8d9cb5-b123-4455-89d1-793cc0ab5a72", "534abca4-9c88-4325-a87e-234e1ff200c8", "20a7c604-005f-4c56-84b9-41e3a2c4d012", "74f97a50-96aa-40ed-9c09-d03d3204df33", "684e22db-338f-4471-adf7-c60c27d39c93", "3920a5e4-e9c4-4548-8853-28660b75a8e7", "505220fd-9844-4f71-b841-348b1daac6ef", "14d7cf8b-1170-4c92-90c7-ee20b67439a8", "c5fb8b81-4df5-4e8f-bcc4-ad7e79378080", "5efa7dab-3bf8-4f2a-9597-42f0b92682bb", "adb465d9-eb97-463b-8d62-696d89290e0f", "235267a4-dd8d-4987-9c6c-e669db9290ce", "44c9f4a9-8b74-424f-b8fd-067ba55ce9ec", "66acd3de-91ac-467f-bf17-90f5b8cb1b35"], "befores": [{"name": "init_driver", "status": "passed", "start": 1678888111780, "stop": 1678888112972}], "afters": [{"name": "init_driver::0", "status": "broken", "statusDetails": {"message": "urllib3.exceptions.MaxRetryError: HTTPConnectionPool(host='localhost', port=55661): Max retries exceeded with url: /session/7375bf4112d9192bd176044077a9d4d3/cookie (Caused by NewConnectionError('<urllib3.connection.HTTPConnection object at 0x7efcae9def50>: Failed to establish a new connection: [Errno 111] Connection refused'))\n", "trace": "  File \"/usr/local/lib/python3.10/dist-packages/allure_commons/_allure.py\", line 221, in __call__\n    return self._fixture_function(*args, **kwargs)\n  File \"/usr/local/lib/python3.10/dist-packages/_pytest/fixtures.py\", line 916, in _teardown_yield_fixture\n    next(it)\n  File \"/home/sujith/codebase/BGE_Framework_Design/Test_Suites/conftest.py\", line 29, in init_driver\n    driver.delete_all_cookies()\n  File \"/home/sujith/.local/lib/python3.10/site-packages/selenium/webdriver/remote/webdriver.py\", line 730, in delete_all_cookies\n    self.execute(Command.DELETE_ALL_COOKIES)\n  File \"/home/sujith/.local/lib/python3.10/site-packages/selenium/webdriver/remote/webdriver.py\", line 442, in execute\n    response = self.command_executor.execute(driver_command, params)\n  File \"/home/sujith/.local/lib/python3.10/site-packages/selenium/webdriver/remote/remote_connection.py\", line 294, in execute\n    return self._request(command_info[0], url, body=data)\n  File \"/home/sujith/.local/lib/python3.10/site-packages/selenium/webdriver/remote/remote_connection.py\", line 316, in _request\n    response = self._conn.request(method, url, body=body, headers=headers)\n  File \"/home/sujith/.local/lib/python3.10/site-packages/urllib3/request.py\", line 74, in request\n    return self.request_encode_url(\n  File \"/home/sujith/.local/lib/python3.10/site-packages/urllib3/request.py\", line 96, in request_encode_url\n    return self.urlopen(method, url, **extra_kw)\n  File \"/home/sujith/.local/lib/python3.10/site-packages/urllib3/poolmanager.py\", line 376, in urlopen\n    response = conn.urlopen(method, u.request_uri, **kw)\n  File \"/home/sujith/.local/lib/python3.10/site-packages/urllib3/connectionpool.py\", line 815, in urlopen\n    return self.urlopen(\n  File \"/home/sujith/.local/lib/python3.10/site-packages/urllib3/connectionpool.py\", line 815, in urlopen\n    return self.urlopen(\n  File \"/home/sujith/.local/lib/python3.10/site-packages/urllib3/connectionpool.py\", line 815, in urlopen\n    return self.urlopen(\n  File \"/home/sujith/.local/lib/python3.10/site-packages/urllib3/connectionpool.py\", line 787, in urlopen\n    retries = retries.increment(\n  File \"/home/sujith/.local/lib/python3.10/site-packages/urllib3/util/retry.py\", line 592, in increment\n    raise MaxRetryError(_pool, url, error or ResponseError(cause))\n"}, "start": 1678888166620, "stop": 1678888166623}], "start": 1678888111780, "stop": 1678888166623}