{"uuid": "baafc6cf-a10b-4d84-8e31-9e319c466d87", "children": ["c30930e3-a621-4d81-bd73-88218a8875b6", "b6544d8d-db17-479b-a1b1-d89fd11a13ad", "5ac6c93e-87cd-4217-b85e-12e2609b780b", "a6d03f71-2007-4881-a3b0-8bc7d0704199", "a17a4b21-5a1a-4e19-9e67-93b4ea42d36b", "5c627933-1b69-4514-9955-5f2335bf2739", "b09bd9db-05fe-472f-9843-475c74dd16b9", "83e4c050-2e3d-40ec-bc2e-1dcf3dd542a3", "150788b3-d7ee-45ae-8517-6d17e0405386", "2c7fb0c9-d788-4e5e-b35b-93b7d26ebd9e", "fc4ff517-0f26-49b5-b74a-21ef9223aebe", "2ea1df6d-bca1-4cff-971c-58504a8f3ffc", "789f2922-87b4-430d-92ae-97406b69fab9", "0995351b-7ea0-41b0-97f1-02c80d6a0501", "0cf63ef0-577b-42fc-ab15-463ca8b73df8", "d7430be9-86b6-4595-a0f4-5786a9bbb1cb", "f89721e6-ace5-4612-bad6-21a13d047cb3"], "befores": [{"name": "init_driver", "status": "passed", "start": 1678876755423, "stop": 1678876756604}], "afters": [{"name": "init_driver::0", "status": "broken", "statusDetails": {"message": "urllib3.exceptions.MaxRetryError: HTTPConnectionPool(host='localhost', port=33033): Max retries exceeded with url: /session/6d5aa946d31d1be43c9b6f876fbae917/cookie (Caused by NewConnectionError('<urllib3.connection.HTTPConnection object at 0x7fb16d881cc0>: Failed to establish a new connection: [Errno 111] Connection refused'))\n", "trace": "  File \"/usr/local/lib/python3.10/dist-packages/allure_commons/_allure.py\", line 221, in __call__\n    return self._fixture_function(*args, **kwargs)\n  File \"/usr/local/lib/python3.10/dist-packages/_pytest/fixtures.py\", line 916, in _teardown_yield_fixture\n    next(it)\n  File \"/home/sujith/codebase/BGE_Framework_Design/Test_Suites/conftest.py\", line 29, in init_driver\n    driver.delete_all_cookies()\n  File \"/home/sujith/.local/lib/python3.10/site-packages/selenium/webdriver/remote/webdriver.py\", line 730, in delete_all_cookies\n    self.execute(Command.DELETE_ALL_COOKIES)\n  File \"/home/sujith/.local/lib/python3.10/site-packages/selenium/webdriver/remote/webdriver.py\", line 442, in execute\n    response = self.command_executor.execute(driver_command, params)\n  File \"/home/sujith/.local/lib/python3.10/site-packages/selenium/webdriver/remote/remote_connection.py\", line 294, in execute\n    return self._request(command_info[0], url, body=data)\n  File \"/home/sujith/.local/lib/python3.10/site-packages/selenium/webdriver/remote/remote_connection.py\", line 316, in _request\n    response = self._conn.request(method, url, body=body, headers=headers)\n  File \"/home/sujith/.local/lib/python3.10/site-packages/urllib3/request.py\", line 74, in request\n    return self.request_encode_url(\n  File \"/home/sujith/.local/lib/python3.10/site-packages/urllib3/request.py\", line 96, in request_encode_url\n    return self.urlopen(method, url, **extra_kw)\n  File \"/home/sujith/.local/lib/python3.10/site-packages/urllib3/poolmanager.py\", line 376, in urlopen\n    response = conn.urlopen(method, u.request_uri, **kw)\n  File \"/home/sujith/.local/lib/python3.10/site-packages/urllib3/connectionpool.py\", line 815, in urlopen\n    return self.urlopen(\n  File \"/home/sujith/.local/lib/python3.10/site-packages/urllib3/connectionpool.py\", line 815, in urlopen\n    return self.urlopen(\n  File \"/home/sujith/.local/lib/python3.10/site-packages/urllib3/connectionpool.py\", line 815, in urlopen\n    return self.urlopen(\n  File \"/home/sujith/.local/lib/python3.10/site-packages/urllib3/connectionpool.py\", line 787, in urlopen\n    retries = retries.increment(\n  File \"/home/sujith/.local/lib/python3.10/site-packages/urllib3/util/retry.py\", line 592, in increment\n    raise MaxRetryError(_pool, url, error or ResponseError(cause))\n"}, "start": 1678876814105, "stop": 1678876814107}], "start": 1678876755423, "stop": 1678876814107}