{"uuid": "01b1fc7b-211e-42c8-87c6-d3de51cfb41a", "children": ["c4758de6-d5d8-48eb-89b5-73bbc6b53649", "795ec630-93fd-4460-9203-ae7051e260a0", "2552b748-0466-4679-b6a8-5b9746e2f09e", "4466e3ae-8dbf-442f-a6e1-e69e6ebd4c81", "af462af6-a9ae-4ceb-b33e-f14a1cbd7128", "30575f02-0a43-4265-8533-bd26c601b4c4", "d58baef8-c74d-4455-b47d-1cda1400f80f", "0f6d91e0-439a-4b61-9baf-4ae3338e8f89", "2f53dd15-038b-4e98-83f4-6d3a63ccdd5e", "8b7a027f-88d8-4bc0-9c82-358ca70e0cd4", "2f4cc17b-5508-4a73-8ea4-8ba01f0b6e09", "6e28cc8c-66f3-4ccc-9ed4-117c77df672c", "f16a70e7-205e-4b7e-ad2f-d7fb3aeed090", "ba9df8dc-c812-4246-b2f8-b42c5a8bf40c", "afe9317a-52f7-49b9-84fa-2738bb69a23b"], "befores": [{"name": "init_driver", "status": "passed", "start": 1678874563728, "stop": 1678874564854}], "afters": [{"name": "init_driver::0", "status": "broken", "statusDetails": {"message": "urllib3.exceptions.MaxRetryError: HTTPConnectionPool(host='localhost', port=46779): Max retries exceeded with url: /session/03d975f8606401b054e1076b0ccf872c/cookie (Caused by NewConnectionError('<urllib3.connection.HTTPConnection object at 0x7fbfc2fe28c0>: Failed to establish a new connection: [Errno 111] Connection refused'))\n", "trace": "  File \"/usr/local/lib/python3.10/dist-packages/allure_commons/_allure.py\", line 221, in __call__\n    return self._fixture_function(*args, **kwargs)\n  File \"/usr/local/lib/python3.10/dist-packages/_pytest/fixtures.py\", line 916, in _teardown_yield_fixture\n    next(it)\n  File \"/home/sujith/codebase/BGE_Framework_Design/Test_Suites/conftest.py\", line 29, in init_driver\n    driver.delete_all_cookies()\n  File \"/home/sujith/.local/lib/python3.10/site-packages/selenium/webdriver/remote/webdriver.py\", line 730, in delete_all_cookies\n    self.execute(Command.DELETE_ALL_COOKIES)\n  File \"/home/sujith/.local/lib/python3.10/site-packages/selenium/webdriver/remote/webdriver.py\", line 442, in execute\n    response = self.command_executor.execute(driver_command, params)\n  File \"/home/sujith/.local/lib/python3.10/site-packages/selenium/webdriver/remote/remote_connection.py\", line 294, in execute\n    return self._request(command_info[0], url, body=data)\n  File \"/home/sujith/.local/lib/python3.10/site-packages/selenium/webdriver/remote/remote_connection.py\", line 316, in _request\n    response = self._conn.request(method, url, body=body, headers=headers)\n  File \"/home/sujith/.local/lib/python3.10/site-packages/urllib3/request.py\", line 74, in request\n    return self.request_encode_url(\n  File \"/home/sujith/.local/lib/python3.10/site-packages/urllib3/request.py\", line 96, in request_encode_url\n    return self.urlopen(method, url, **extra_kw)\n  File \"/home/sujith/.local/lib/python3.10/site-packages/urllib3/poolmanager.py\", line 376, in urlopen\n    response = conn.urlopen(method, u.request_uri, **kw)\n  File \"/home/sujith/.local/lib/python3.10/site-packages/urllib3/connectionpool.py\", line 815, in urlopen\n    return self.urlopen(\n  File \"/home/sujith/.local/lib/python3.10/site-packages/urllib3/connectionpool.py\", line 815, in urlopen\n    return self.urlopen(\n  File \"/home/sujith/.local/lib/python3.10/site-packages/urllib3/connectionpool.py\", line 815, in urlopen\n    return self.urlopen(\n  File \"/home/sujith/.local/lib/python3.10/site-packages/urllib3/connectionpool.py\", line 787, in urlopen\n    retries = retries.increment(\n  File \"/home/sujith/.local/lib/python3.10/site-packages/urllib3/util/retry.py\", line 592, in increment\n    raise MaxRetryError(_pool, url, error or ResponseError(cause))\n"}, "start": 1678874609547, "stop": 1678874609550}], "start": 1678874563728, "stop": 1678874609550}