{"uuid": "601683ad-b2c2-4ef2-bcb1-83a2510570c4", "children": ["132f7a2b-0658-44ee-a2b7-56996b3530f1", "6ed3b035-320a-49ed-a0fd-a34036c8c69d", "d646a2fd-0f31-425c-b5af-9f1be4333439", "d4909757-7969-4010-9b4c-c1a8343cee76", "6845a927-2703-4864-bf9f-ff46e479e929", "b036146e-611b-4c69-960c-043b4b96c915", "18b3c27d-03f0-4f32-8da9-e94165f9af7a", "63e2feef-a960-4f3b-96ab-c594e6390481", "3ca1552b-91a2-4c90-ba64-ba133baa4abc", "c6ce4f5f-ba4c-4f29-892c-2856d4a5205b", "40402e4f-91fb-4479-805a-af7c71b74e26", "7885fce4-cbd8-41da-b6c4-7f47411acaf7", "0089b63e-8d1b-4436-9ef6-563dcdf89db3", "05049c1d-9d61-4c32-9288-4ab1a9571c68"], "befores": [{"name": "init_driver", "status": "passed", "start": 1678887954117, "stop": 1678887955267}], "afters": [{"name": "init_driver::0", "status": "broken", "statusDetails": {"message": "urllib3.exceptions.MaxRetryError: HTTPConnectionPool(host='localhost', port=38173): Max retries exceeded with url: /session/23429ece6369fce9b644399883aed215/cookie (Caused by NewConnectionError('<urllib3.connection.HTTPConnection object at 0x7ff4659dead0>: Failed to establish a new connection: [Errno 111] Connection refused'))\n", "trace": "  File \"/usr/local/lib/python3.10/dist-packages/allure_commons/_allure.py\", line 221, in __call__\n    return self._fixture_function(*args, **kwargs)\n  File \"/usr/local/lib/python3.10/dist-packages/_pytest/fixtures.py\", line 916, in _teardown_yield_fixture\n    next(it)\n  File \"/home/sujith/codebase/BGE_Framework_Design/Test_Suites/conftest.py\", line 29, in init_driver\n    driver.delete_all_cookies()\n  File \"/home/sujith/.local/lib/python3.10/site-packages/selenium/webdriver/remote/webdriver.py\", line 730, in delete_all_cookies\n    self.execute(Command.DELETE_ALL_COOKIES)\n  File \"/home/sujith/.local/lib/python3.10/site-packages/selenium/webdriver/remote/webdriver.py\", line 442, in execute\n    response = self.command_executor.execute(driver_command, params)\n  File \"/home/sujith/.local/lib/python3.10/site-packages/selenium/webdriver/remote/remote_connection.py\", line 294, in execute\n    return self._request(command_info[0], url, body=data)\n  File \"/home/sujith/.local/lib/python3.10/site-packages/selenium/webdriver/remote/remote_connection.py\", line 316, in _request\n    response = self._conn.request(method, url, body=body, headers=headers)\n  File \"/home/sujith/.local/lib/python3.10/site-packages/urllib3/request.py\", line 74, in request\n    return self.request_encode_url(\n  File \"/home/sujith/.local/lib/python3.10/site-packages/urllib3/request.py\", line 96, in request_encode_url\n    return self.urlopen(method, url, **extra_kw)\n  File \"/home/sujith/.local/lib/python3.10/site-packages/urllib3/poolmanager.py\", line 376, in urlopen\n    response = conn.urlopen(method, u.request_uri, **kw)\n  File \"/home/sujith/.local/lib/python3.10/site-packages/urllib3/connectionpool.py\", line 815, in urlopen\n    return self.urlopen(\n  File \"/home/sujith/.local/lib/python3.10/site-packages/urllib3/connectionpool.py\", line 815, in urlopen\n    return self.urlopen(\n  File \"/home/sujith/.local/lib/python3.10/site-packages/urllib3/connectionpool.py\", line 815, in urlopen\n    return self.urlopen(\n  File \"/home/sujith/.local/lib/python3.10/site-packages/urllib3/connectionpool.py\", line 787, in urlopen\n    retries = retries.increment(\n  File \"/home/sujith/.local/lib/python3.10/site-packages/urllib3/util/retry.py\", line 592, in increment\n    raise MaxRetryError(_pool, url, error or ResponseError(cause))\n"}, "start": 1678888014194, "stop": 1678888014197}], "start": 1678887954117, "stop": 1678888014197}