{"uuid": "fb88dbcb-01eb-406f-b4f8-1606e0f0a83a", "children": ["06cf8f1b-8aa6-4b94-946f-c15747cd6ee2", "33f3afb0-cf25-44ef-b241-184a11403cf2", "9cbcc801-edf0-4eb1-9922-5e9988390745", "a41c8091-356d-46a0-b318-a08f567a5cf6", "4227ddd0-45bf-4144-a6ba-f2e466b2c5d9", "d517dab3-006b-4b7a-849f-26b6b6707a4a", "b9bd25d2-4b11-4688-904f-12a6c8a83dc4", "1541edb0-2450-413c-b7a7-aef99ffbe0a7", "4b8523e9-daef-453f-9e16-2563bac4648f", "6e5bea39-11c9-49d7-83f6-5990ca5ced51", "ea6eca4f-09ea-4938-a89f-afb1b4776f02", "5a094943-6fd2-4a5e-a4eb-f2a61c3f9e59", "5cd5c20b-9a3a-42b7-8c49-5f4a5ca54f51", "04dc4482-1a4d-483f-8485-50cfc2b7f59d"], "befores": [{"name": "init_driver", "status": "passed", "start": 1678884681773, "stop": 1678884682932}], "afters": [{"name": "init_driver::0", "status": "broken", "statusDetails": {"message": "urllib3.exceptions.MaxRetryError: HTTPConnectionPool(host='localhost', port=52295): Max retries exceeded with url: /session/ec314e00f17d1e9fdb71d0febacb41db/cookie (Caused by NewConnectionError('<urllib3.connection.HTTPConnection object at 0x7f71887d6bc0>: Failed to establish a new connection: [Errno 111] Connection refused'))\n", "trace": "  File \"/usr/local/lib/python3.10/dist-packages/allure_commons/_allure.py\", line 221, in __call__\n    return self._fixture_function(*args, **kwargs)\n  File \"/usr/local/lib/python3.10/dist-packages/_pytest/fixtures.py\", line 916, in _teardown_yield_fixture\n    next(it)\n  File \"/home/sujith/codebase/BGE_Framework_Design/Test_Suites/conftest.py\", line 29, in init_driver\n    driver.delete_all_cookies()\n  File \"/home/sujith/.local/lib/python3.10/site-packages/selenium/webdriver/remote/webdriver.py\", line 730, in delete_all_cookies\n    self.execute(Command.DELETE_ALL_COOKIES)\n  File \"/home/sujith/.local/lib/python3.10/site-packages/selenium/webdriver/remote/webdriver.py\", line 442, in execute\n    response = self.command_executor.execute(driver_command, params)\n  File \"/home/sujith/.local/lib/python3.10/site-packages/selenium/webdriver/remote/remote_connection.py\", line 294, in execute\n    return self._request(command_info[0], url, body=data)\n  File \"/home/sujith/.local/lib/python3.10/site-packages/selenium/webdriver/remote/remote_connection.py\", line 316, in _request\n    response = self._conn.request(method, url, body=body, headers=headers)\n  File \"/home/sujith/.local/lib/python3.10/site-packages/urllib3/request.py\", line 74, in request\n    return self.request_encode_url(\n  File \"/home/sujith/.local/lib/python3.10/site-packages/urllib3/request.py\", line 96, in request_encode_url\n    return self.urlopen(method, url, **extra_kw)\n  File \"/home/sujith/.local/lib/python3.10/site-packages/urllib3/poolmanager.py\", line 376, in urlopen\n    response = conn.urlopen(method, u.request_uri, **kw)\n  File \"/home/sujith/.local/lib/python3.10/site-packages/urllib3/connectionpool.py\", line 815, in urlopen\n    return self.urlopen(\n  File \"/home/sujith/.local/lib/python3.10/site-packages/urllib3/connectionpool.py\", line 815, in urlopen\n    return self.urlopen(\n  File \"/home/sujith/.local/lib/python3.10/site-packages/urllib3/connectionpool.py\", line 815, in urlopen\n    return self.urlopen(\n  File \"/home/sujith/.local/lib/python3.10/site-packages/urllib3/connectionpool.py\", line 787, in urlopen\n    retries = retries.increment(\n  File \"/home/sujith/.local/lib/python3.10/site-packages/urllib3/util/retry.py\", line 592, in increment\n    raise MaxRetryError(_pool, url, error or ResponseError(cause))\n"}, "start": 1678884738074, "stop": 1678884738077}], "start": 1678884681773, "stop": 1678884738077}