{"uuid": "2e98ac2c-ef6f-4556-93b1-898d87eb5905", "children": ["2544d1b2-dfec-4af5-928b-b18db6bb4297", "b6df288c-2a6f-4d43-8f72-7b39fe1c4206", "fc86a626-1637-4557-9eeb-943ef016889c", "93ee2b5d-7a8b-4d59-9e87-2eda7548ef54", "f34b74c4-0a5d-4324-9636-76cd69ed693c", "f4e59d4b-daa2-4900-996f-40888328eda2", "2d25b1d1-e758-476a-8c17-516b9d0e88b5", "e48a38ab-620d-4b55-af45-ee5e62861e7e", "856809f7-e013-4fa6-ac05-ffcec7d1ac10", "6e27825f-702e-477f-9ad6-6beae1271046", "9fa25b3f-41aa-485f-aa0d-9e24165c1c89", "d91dc0a2-74c5-406c-8861-07b01b1af799", "020a61e7-8d0c-4784-8201-391e7123df1d", "89b04f4b-75b8-48fc-a682-c4718f9a3159"], "befores": [{"name": "init_driver", "status": "passed", "start": 1678885148819, "stop": 1678885149991}], "afters": [{"name": "init_driver::0", "status": "broken", "statusDetails": {"message": "urllib3.exceptions.MaxRetryError: HTTPConnectionPool(host='localhost', port=37115): Max retries exceeded with url: /session/2d45cfe52018b636b4d075a70874e514/cookie (Caused by NewConnectionError('<urllib3.connection.HTTPConnection object at 0x7f3d1d686b90>: Failed to establish a new connection: [Errno 111] Connection refused'))\n", "trace": "  File \"/usr/local/lib/python3.10/dist-packages/allure_commons/_allure.py\", line 221, in __call__\n    return self._fixture_function(*args, **kwargs)\n  File \"/usr/local/lib/python3.10/dist-packages/_pytest/fixtures.py\", line 916, in _teardown_yield_fixture\n    next(it)\n  File \"/home/sujith/codebase/BGE_Framework_Design/Test_Suites/conftest.py\", line 29, in init_driver\n    driver.delete_all_cookies()\n  File \"/home/sujith/.local/lib/python3.10/site-packages/selenium/webdriver/remote/webdriver.py\", line 730, in delete_all_cookies\n    self.execute(Command.DELETE_ALL_COOKIES)\n  File \"/home/sujith/.local/lib/python3.10/site-packages/selenium/webdriver/remote/webdriver.py\", line 442, in execute\n    response = self.command_executor.execute(driver_command, params)\n  File \"/home/sujith/.local/lib/python3.10/site-packages/selenium/webdriver/remote/remote_connection.py\", line 294, in execute\n    return self._request(command_info[0], url, body=data)\n  File \"/home/sujith/.local/lib/python3.10/site-packages/selenium/webdriver/remote/remote_connection.py\", line 316, in _request\n    response = self._conn.request(method, url, body=body, headers=headers)\n  File \"/home/sujith/.local/lib/python3.10/site-packages/urllib3/request.py\", line 74, in request\n    return self.request_encode_url(\n  File \"/home/sujith/.local/lib/python3.10/site-packages/urllib3/request.py\", line 96, in request_encode_url\n    return self.urlopen(method, url, **extra_kw)\n  File \"/home/sujith/.local/lib/python3.10/site-packages/urllib3/poolmanager.py\", line 376, in urlopen\n    response = conn.urlopen(method, u.request_uri, **kw)\n  File \"/home/sujith/.local/lib/python3.10/site-packages/urllib3/connectionpool.py\", line 815, in urlopen\n    return self.urlopen(\n  File \"/home/sujith/.local/lib/python3.10/site-packages/urllib3/connectionpool.py\", line 815, in urlopen\n    return self.urlopen(\n  File \"/home/sujith/.local/lib/python3.10/site-packages/urllib3/connectionpool.py\", line 815, in urlopen\n    return self.urlopen(\n  File \"/home/sujith/.local/lib/python3.10/site-packages/urllib3/connectionpool.py\", line 787, in urlopen\n    retries = retries.increment(\n  File \"/home/sujith/.local/lib/python3.10/site-packages/urllib3/util/retry.py\", line 592, in increment\n    raise MaxRetryError(_pool, url, error or ResponseError(cause))\n"}, "start": 1678885193185, "stop": 1678885193188}], "start": 1678885148819, "stop": 1678885193188}