{"uuid": "1f51b872-b47b-4036-8a66-173c8281966a", "children": ["53a7ed69-6513-42cd-9546-ac0eefca31ea", "27201422-2566-4543-9796-f1f2002f192c", "a6e40a27-6d1c-45ba-a661-8eb8d1f86984", "b83945ae-22fb-40ac-8660-4f9ad1ab68d1", "0ca6394a-7a7e-457b-aecb-11e9c9d12c28", "8a7f4882-cebd-4f2c-a2a4-8c182bd73486", "ef94bc0f-c6ed-4046-ac43-bb19e1c12b3c", "bcce7256-2b14-486c-b081-0eb376c21a50", "ae727483-78f0-4175-8cbd-87b57fb85283", "19c42afc-b7a7-4c0b-b3bb-fb22a60a449c", "132bbdbb-0827-4f1d-9dbb-0896682fa499", "c21e41ad-410f-41e4-af08-18af46161fb2", "2d766f22-6b7c-4144-8d95-de9a42d60d12", "73a98434-28b8-4cb7-87ea-50f861746e35"], "befores": [{"name": "init_driver", "status": "passed", "start": 1678885420514, "stop": 1678885421683}], "afters": [{"name": "init_driver::0", "status": "broken", "statusDetails": {"message": "urllib3.exceptions.MaxRetryError: HTTPConnectionPool(host='localhost', port=46215): Max retries exceeded with url: /session/dfd81cece30765bb926bcf917ad8ab79/cookie (Caused by NewConnectionError('<urllib3.connection.HTTPConnection object at 0x7f27983d6bc0>: Failed to establish a new connection: [Errno 111] Connection refused'))\n", "trace": "  File \"/usr/local/lib/python3.10/dist-packages/allure_commons/_allure.py\", line 221, in __call__\n    return self._fixture_function(*args, **kwargs)\n  File \"/usr/local/lib/python3.10/dist-packages/_pytest/fixtures.py\", line 916, in _teardown_yield_fixture\n    next(it)\n  File \"/home/sujith/codebase/BGE_Framework_Design/Test_Suites/conftest.py\", line 29, in init_driver\n    driver.delete_all_cookies()\n  File \"/home/sujith/.local/lib/python3.10/site-packages/selenium/webdriver/remote/webdriver.py\", line 730, in delete_all_cookies\n    self.execute(Command.DELETE_ALL_COOKIES)\n  File \"/home/sujith/.local/lib/python3.10/site-packages/selenium/webdriver/remote/webdriver.py\", line 442, in execute\n    response = self.command_executor.execute(driver_command, params)\n  File \"/home/sujith/.local/lib/python3.10/site-packages/selenium/webdriver/remote/remote_connection.py\", line 294, in execute\n    return self._request(command_info[0], url, body=data)\n  File \"/home/sujith/.local/lib/python3.10/site-packages/selenium/webdriver/remote/remote_connection.py\", line 316, in _request\n    response = self._conn.request(method, url, body=body, headers=headers)\n  File \"/home/sujith/.local/lib/python3.10/site-packages/urllib3/request.py\", line 74, in request\n    return self.request_encode_url(\n  File \"/home/sujith/.local/lib/python3.10/site-packages/urllib3/request.py\", line 96, in request_encode_url\n    return self.urlopen(method, url, **extra_kw)\n  File \"/home/sujith/.local/lib/python3.10/site-packages/urllib3/poolmanager.py\", line 376, in urlopen\n    response = conn.urlopen(method, u.request_uri, **kw)\n  File \"/home/sujith/.local/lib/python3.10/site-packages/urllib3/connectionpool.py\", line 815, in urlopen\n    return self.urlopen(\n  File \"/home/sujith/.local/lib/python3.10/site-packages/urllib3/connectionpool.py\", line 815, in urlopen\n    return self.urlopen(\n  File \"/home/sujith/.local/lib/python3.10/site-packages/urllib3/connectionpool.py\", line 815, in urlopen\n    return self.urlopen(\n  File \"/home/sujith/.local/lib/python3.10/site-packages/urllib3/connectionpool.py\", line 787, in urlopen\n    retries = retries.increment(\n  File \"/home/sujith/.local/lib/python3.10/site-packages/urllib3/util/retry.py\", line 592, in increment\n    raise MaxRetryError(_pool, url, error or ResponseError(cause))\n"}, "start": 1678885469070, "stop": 1678885469073}], "start": 1678885420514, "stop": 1678885469073}